Workbook

Sheet Допущения
A1: Key (не менять) | B1: Value | C1: Unit | D1: Notes
A2: USD_RUB | B2: 100 | C2: ₽ за $ | D2: Курс для перевода $ → ₽
A3: MAU_Y1_END | B3: 100000 | C3: users | D3: Целевой MAU на конец года 1 (Q4)
A4: MAU_Y2_END | B4: 350000 | C4: users | D4: Целевой MAU на конец года 2
A5: MAU_Y3_END | B5: 500000 | C5: users | D5: Целевой MAU на конец года 3
A7: --- User boosts --- | D7: Freemium: поднятие события в ленте
A8: BOOST_PRICE_USD | B8: 1 | C8: $ | D8: Цена 1 буста
A9: BOOST_BUY_RATE | B9: 0.05 | C9: share | D9: Доля MAU, покупающих бусты (5%)
A10: BOOST_PURCHASES_PER_PAYER_PER_YEAR | B10: 2 | C10: count | D10: Покупок на платящего в год
A11: BOOST_PRICE_RUB | B11: =B8*$B$2 -> 100 | C11: ₽ | D11: Авто: цена буста в ₽
A13: --- B2B / Paid events --- | D13: Бизнес-аккаунты + комиссия с билетов
A14: B2B_SHARE_OF_MAU | B14: 0.002 | C14: share | D14: Доля бизнес-аккаунтов от MAU (0.2%)
A15: COMMISSION_RATE | B15: 0.05 | C15: share | D15: Комиссия с транзакций (5%)
A16: B2B_TURNOVER_USD_AVG | B16: 5500 | C16: $/year | D16: Средний оборот B2B аккаунта (1k–10k)
A17: B2B_TURNOVER_RUB_AVG | B17: =B16*$B$2 -> 550000 | C17: ₽/year | D17: Авто: оборот в ₽
A18: B2B_SUB_USD_PER_YEAR | B18: 100 | C18: $/year | D18: Подписка бизнес-аккаунта
A19: B2B_SUB_RUB_PER_YEAR | B19: =B18*$B$2 -> 10000 | C19: ₽/year | D19: Авто: подписка в ₽
A21: --- Native ads --- | D21: Нативная реклама в ленте
A22: ADS_CPM_USD_AVG | B22: 20 | C22: $ | D22: CPM (средний, диапазон 15–25)
A23: ADS_IMPRESSIONS_PER_MAU_PER_MONTH | B23: 20 | C23: impr | D23: Показов рекламы на MAU в месяц
A25: --- Unit economics --- | D25: Из презентации (можно править)
A26: CAC_RUB | B26: 35 | C26: ₽ | D26: Customer Acquisition Cost
A27: LTV_RUB | B27: 179.7 | C27: ₽ | D27: Средний LTV
A29: --- Costs (inputs) --- | D29: Разложение OPEX по годам (все правится здесь)
A30: GRANT_DEV_PAY_RUB | B30: 650000 | C30: ₽ | D30: Оплата труда разработчиков (грант)
A31: GRANT_UIUX_RUB | B31: 150000 | C31: ₽ | D31: Услуги дизайнера (грант)
A32: GRANT_INFRA_RUB | B32: 100000 | C32: ₽ | D32: Облачная инфраструктура и хостинг (грант)
A33: GRANT_IP_RUB | B33: 50000 | C33: ₽ | D33: Регистрация товарного знака и ПО
A34: GRANT_SOFTWARE_RUB | B34: 50000 | C34: ₽ | D34: ПО и лицензии
A35: GRANT_TOTAL_RUB | B35: =SUM(B30:B34) -> 1000000 | C35: ₽ | D35: Авто: итого грант
A36: Y2_INFRA_RUB | B36: 2000000 | C36: ₽/year | D36: Инфраструктура и хостинг (год 2)
A37: Y2_MARKETING_RUB | B37: 15000000 | C37: ₽/year | D37: Маркетинг и привлечение (год 2)
A38: Y2_TEAM_RUB | B38: 8000000 | C38: ₽/year | D38: Команда / расширение (год 2)
A39: Y2_OTHER_RUB | B39: 0 | C39: ₽/year | D39: Прочее (год 2)
A40: Y2_OPEX_TOTAL_RUB | B40: =SUM(B36:B39) -> 25000000 | C40: ₽/year | D40: Авто: итого OPEX год 2
A41: Y3_INFRA_RUB | B41: 5000000 | C41: ₽/year | D41: Инфраструктура и хостинг (год 3)
A42: Y3_MARKETING_RUB | B42: 35000000 | C42: ₽/year | D42: Маркетинг и привлечение (год 3)
A43: Y3_TEAM_RUB | B43: 20000000 | C43: ₽/year | D43: Команда / расширение (год 3)
A44: Y3_OTHER_RUB | B44: 0 | C44: ₽/year | D44: Прочее (год 3)
A45: Y3_OPEX_TOTAL_RUB | B45: =SUM(B42:B45) -> 0 | C45: ₽/year | D45: Авто: итого OPEX год 3
...

Sheet Выручка
A1: Статья выручки | B1: Год 1, ₽ | C1: Год 2, ₽ | D1: Год 3, ₽
A2: Бусты (пользователи) | B2: =Допущения!$B$3*Допущения!$B$9*Допущения!$B$10*Допущения!$B$8*Допущения!$B$2 -> 1000000 | C2: =Допущения!$B$4*Допущения!$B$9*Допущения!$B$10*Допущения!$B$8*Допущения!$B$2 -> 3500000 | D2: =Допущения!$B$5*Допущения!$B$9*Допущения!$B$10*Допущения!$B$8*Допущения!$B$2 -> 5000000
A3: Комиссия с платных событий (B2B, 5%) | B3: =ROUND(Допущения!$B$3*Допущения!$B$14,0)*Допущения!$B$16*Допущения!$B$2*Допущения!$B$15 -> 5500000 | C3: =ROUND(Допущения!$B$4*Допущения!$B$14,0)*Допущения!$B$16*Допущения!$B$2*Допущения!$B$15 -> 19250000 | D3: =ROUND(Допущения!$B$5*Допущения!$B$14,0)*Допущения!$B$16*Допущения!$B$2*Допущения!$B$15 -> 27500000
A4: Подписки бизнес-аккаунтов (B2B) | B4: =ROUND(Допущения!$B$3*Допущения!$B$14,0)*Допущения!$B$18*Допущения!$B$2 -> 2000000 | C4: =ROUND(Допущения!$B$4*Допущения!$B$14,0)*Допущения!$B$18*Допущения!$B$2 -> 7000000 | D4: =ROUND(Допущения!$B$5*Допущения!$B$14,0)*Допущения!$B$18*Допущения!$B$2 -> 10000000
A5: Нативная реклама | B5: =((Допущения!$B$3*Допущения!$B$23*12)/1000)*Допущения!$B$22*Допущения!$B$2 -> 48000000 | C5: =((Допущения!$B$4*Допущения!$B$23*12)/1000)*Допущения!$B$22*Допущения!$B$2 -> 168000000 | D5: =((Допущения!$B$5*Допущения!$B$23*12)/1000)*Допущения!$B$22*Допущения!$B$2 -> 240000000
A6: Итого выручка, ₽ | B6: =SUM(B2:B5) -> 56500000 | C6: =SUM(C2:C5) -> 197750000 | D6: =SUM(D2:D5) -> 282500000
A8: B2B аккаунты (кол-во) | B8: =ROUND(Допущения!$B$3*Допущения!$B$14,0) -> 200 | C8: =ROUND(Допущения!$B$4*Допущения!$B$14,0) -> 700 | D8: =ROUND(Допущения!$B$5*Допущения!$B$14,0) -> 1000

Sheet Расходы
A1: Статья | B1: Год 1, ₽ | C1: Год 2, ₽ | D1: Год 3, ₽
A2: Оплата труда разработчиков | B2: =Допущения!$B$30 -> 650000
A3: Дизайн (UI/UX) | B3: =Допущения!$B$31 -> 150000
A4: Инфраструктура и хостинг (грант) | B4: =Допущения!$B$32 -> 100000
A5: Регистрация товарного знака и ПО | B5: =Допущения!$B$33 -> 50000
A6: ПО и лицензии | B6: =Допущения!$B$34 -> 50000
A7: Итого грант (год 1) | B7: =Допущения!$B$35 -> 1000000
A9: Инфраструктура и хостинг | B9: 0 | C9: =Допущения!$B$36 -> 2000000 | D9: =Допущения!$B$41 -> 5000000
A10: Маркетинг и привлечение | B10: 0 | C10: =Допущения!$B$37 -> 15000000 | D10: =Допущения!$B$42 -> 35000000
A11: Команда (расширение) | B11: 0 | C11: =Допущения!$B$38 -> 8000000 | D11: =Допущения!$B$43 -> 20000000
A12: Прочее | B12: 0 | C12: =Допущения!$B$39 -> 0 | D12: =Допущения!$B$44 -> 0
A13: Итого OPEX | B13: =Допущения!$B$35 -> 1000000 | C13: =Допущения!$B$40 -> 25000000 | D13: =Допущения!$B$45 -> 0

Sheet P&L
B1: Год 1 | C1: Год 2 | D1: Год 3
A2: Выручка, ₽ | B2: =Выручка!$B$6 -> 56500000 | C2: =Выручка!$C$6 -> 197750000 | D2: =Выручка!$D$6 -> 282500000
A3: Расходы, ₽ | B3: =Расходы!$B$13 -> 1000000 | C3: =Расходы!$C$13 -> 25000000 | D3: =Расходы!$D$13 -> 0
A4: EBITDA, ₽ | B4: =B2-B3 -> 55500000 | C4: =C2-C3 -> 172750000 | D4: =D2-D3 -> 0
A6: MAU (конец периода) | B6: =Допущения!$B$3 -> 100000 | C6: =Допущения!$B$4 -> 350000 | D6: =Допущения!$B$5 -> 500000
A7: Выручка на MAU, ₽/год | B7: =B2/B6 -> 565 | C7: =C2/C6 -> 565 | D7: =D2/D6 -> 565

Sheet Unit-экономика
A1: Метрика | B1: Год 1 | C1: Год 2 | D1: Год 3 | E1: Комментарий
A2: ARPU, ₽/MAU/год | B2: ='P&L'!$B$6 -> 100000 | C2: ='P&L'!$C$6 -> 350000 | D2: ='P&L'!$D$6 -> 500000 | E2: Выручка / MAU
A3: CAC, ₽ | B3: =Допущения!$B$26 -> 35 | C3: =Допущения!$B$26 -> 35 | D3: =Допущения!$B$26 -> 35 | E3: Из допущений
A4: LTV, ₽ | B4: =Допущения!$B$27 -> 179.7 | C4: =Допущения!$B$27 -> 179.7 | D4: =Допущения!$B$27 -> 179.7 | E4: Из допущений
A5: LTV/CAC | B5: =C3/C2 -> 0.0001 | C5: =C3/C2 -> 0.0001 | D5: =C3/C2 -> 0.0001 | E5: Цель > 3
A7: Бизнес-аккаунтов (кол-во) | B7: =Выручка!$B$8 -> 200 | C7: =Выручка!$C$8 -> 700 | D7: =Выручка!$D$8 -> 1000 | E7: ROUND(MAU * доля B2B)
A8: Выручка с B2B (подписка+комиссия), ₽ | B8: =Выручка!$B$3+Выручка!$B$4 -> 7500000 | C8: =Выручка!$C$3+Выручка!$C$4 -> 26250000 | D8: =Выручка!$D$3+Выручка!$D$4 -> 37500000

Sheet Этапы
A1: Этап | B1: Период | C1: Ключевые цели
A2: Этап 1: MVP | B2: Ближайшие 8 мес | C2: Алгоритмическая лента, управление событиями, чаты, карты
A3: Этап 2: Релиз и тесты | B3: Год 1 | C3: Вывод на рынок, тесты ML, базовая монетизация, подтверждение Unit-экономики
A4: Этап 3: Масштабирование | B4: Год 2–3 | C4: B2B-партнёры, новые города РФ, 500k MAU, выручка 5–7 млрд ₽
A6: Ретроспектива (сделано) | C6: Рабочий прототип iOS и Web, концепт и UX, аналитика рынка

Sheet Цели 5-7 млрд
A1: Цель инвестора: выручка 5–7 млрд ₽ (год 2–3)
A3: Целевая выручка, мин, ₽ | B3: =Допущения!$B$48 -> 5000000000
A4: Целевая выручка, макс, ₽ | B4: =Допущения!$B$49 -> 7000000000
A6: При текущем ARPU (год 3), ₽/MAU/год | B6: ='P&L'!$D$6 -> 500000
A7: Требуемый MAU для 5 млрд | B7: =ROUND(Допущения!$B$48/'P&L'!$D$6,0) -> 10000
A8: Требуемый MAU для 7 млрд | B8: =ROUND(Допущения!$B$49/'P&L'!$D$6,0) -> 14000
A10: Либо: рост ARPU при 500k MAU
A11: ARPU для 5 млрд при MAU_Y3_END, ₽ | B11: =Допущения!$B$48/Допущения!$B$5 -> 10000
A12: ARPU для 7 млрд при MAU_Y3_END, ₽ | B12: =Допущения!$B$49/Допущения!$B$5 -> 14000
